<?xml version="1.0" encoding="utf-8"?>
<!-- This URDF was automatically created by SolidWorks to URDF Exporter! Originally created by Stephen Brawner (brawner@gmail.com) 
     Commit Version: 1.5.1-0-g916b5db  Build Version: 1.5.7152.31018
     For more information, please see http://wiki.ros.org/sw_urdf_exporter -->
<robot
  name="bot_description" xmlns:xacro="http://www.ros.org/wiki/xacro">
  <link
    name="base_link">
    <inertial>
      <origin
        xyz="-0.040436 -0.3851 0.1295"
        rpy="0 0 0" />
      <mass
        value="3" />
      <inertia
        ixx="0.012939"
        ixy="-1.7356E-07"
        ixz="-9.2877E-07"
        iyy="0.013081"
        iyz="5.526E-09"
        izz="0.025689" />
    </inertial>
    <visual>
      <origin
        xyz="0 0 0"
        rpy="0 0 0" />
      <geometry>
        <mesh
          filename="package://bot_description/meshes/base_link.STL" />
      </geometry>
      <material
        name="">
        <color
          rgba="0 0 0.93333 1" />
      </material>
    </visual>
    <collision>
      <origin
        xyz="0 0 0"
        rpy="0 0 0" />
      <geometry>
        <mesh
          filename="package://bot_description/meshes/base_link.STL" />
      </geometry>
    </collision>
  </link>
  <link
    name="rf_wheel">
    <inertial>
      <origin
        xyz="1.1082E-07 0.021961 1.2751E-07"
        rpy="0 0 0" />
      <mass
        value="0.24035" />
      <inertia
        ixx="0.00013963"
        ixy="-6.8362E-10"
        ixz="-7.7213E-11"
        iyy="0.00027302"
        iyz="7.1636E-10"
        izz="0.00013963" />
    </inertial>
    <visual>
      <origin
        xyz="0 0 0"
        rpy="0 0 0" />
      <geometry>
        <mesh
          filename="package://bot_description/meshes/rf_wheel.STL" />
      </geometry>
      <material
        name="">
        <color
          rgba="0 1 0 1" />
      </material>
    </visual>
    <collision>
      <origin
        xyz="0 0 0"
        rpy="0 0 0" />
      <geometry>
        <mesh
          filename="package://bot_description/meshes/rf_wheel.STL" />
      </geometry>
    </collision>
  </link>
  <joint
    name="rfjoint"
    type="continuous">
    <origin
      xyz="-0.20094 -0.14188 0.069457"
      rpy="3.1416 0 0" />
    <parent
      link="base_link" />
    <child
      link="rf_wheel" />
    <axis
      xyz="0 1 0" />
    <limit
      effort="100"
      velocity="2" />
  </joint>
  <link
    name="lf_wheel">
    <inertial>
      <origin
        xyz="1.1082E-07 -0.020842 1.2751E-07"
        rpy="0 0 0" />
      <mass
        value="0.24035" />
      <inertia
        ixx="0.00013963"
        ixy="-6.8362E-10"
        ixz="-7.7213E-11"
        iyy="0.00027302"
        iyz="7.1636E-10"
        izz="0.00013963" />
    </inertial>
    <visual>
      <origin
        xyz="0 0 0"
        rpy="0 0 0" />
      <geometry>
        <mesh
          filename="package://bot_description/meshes/lf_wheel.STL" />
      </geometry>
      <material
        name="">
        <color
          rgba="0 1 0 1" />
      </material>
    </visual>
    <collision>
      <origin
        xyz="0 0 0"
        rpy="0 0 0" />
      <geometry>
        <mesh
          filename="package://bot_description/meshes/lf_wheel.STL" />
      </geometry>
    </collision>
  </link>
  <joint
    name="lfjoint"
    type="continuous">
    <origin
      xyz="-0.20094 -0.59 0.069457"
      rpy="0 0 0" />
    <parent
      link="base_link" />
    <child
      link="lf_wheel" />
    <axis
      xyz="0 -1 0" />
    <limit
      effort="100"
      velocity="2" />
  </joint>
  <link
    name="rb_wheel">
    <inertial>
      <origin
        xyz="0 -1.3878E-17 0.015"
        rpy="0 0 0" />
      <mass
        value="0.34848" />
      <inertia
        ixx="0.00060618"
        ixy="-7.6219E-37"
        ixz="-2.0514E-22"
        iyy="0.00060618"
        iyz="-2.0536E-36"
        izz="0.001173" />
    </inertial>
    <visual>
      <origin
        xyz="0 0 0"
        rpy="0 0 0" />
      <geometry>
        <mesh
          filename="package://bot_description/meshes/rb_wheel.STL" />
      </geometry>
      <material
        name="">
        <color
          rgba="0 1 0 1" />
      </material>
    </visual>
    <collision>
      <origin
        xyz="0 0 0"
        rpy="0 0 0" />
      <geometry>
        <mesh
          filename="package://bot_description/meshes/rb_wheel.STL" />
      </geometry>
    </collision>
  </link>
  <joint
    name="rbjoint"
    type="continuous">
    <origin
      xyz="0.11906 -0.15734 0.069457"
      rpy="1.5708 0 0" />
    <parent
      link="base_link" />
    <child
      link="rb_wheel" />
    <axis
      xyz="0 0 1" />
    <limit
      effort="100"
      velocity="2" />
  </joint>
  <link
    name="lb_wheel">
    <inertial>
      <origin
        xyz="3.4278E-15 1.3878E-17 0.015"
        rpy="0 0 0" />
      <mass
        value="0.34848" />
      <inertia
        ixx="0.00060618"
        ixy="-7.6219E-37"
        ixz="-1.2081E-36"
        iyy="0.00060618"
        iyz="-2.0536E-36"
        izz="0.001173" />
    </inertial>
    <visual>
      <origin
        xyz="0 0 0"
        rpy="0 0 0" />
      <geometry>
        <mesh
          filename="package://bot_description/meshes/lb_wheel.STL" />
      </geometry>
      <material
        name="">
        <color
          rgba="0 1 0 1" />
      </material>
    </visual>
    <collision>
      <origin
        xyz="0 0 0"
        rpy="0 0 0" />
      <geometry>
        <mesh
          filename="package://bot_description/meshes/lb_wheel.STL" />
      </geometry>
    </collision>
  </link>
  <joint
    name="lbjoint"
    type="continuous">
    <origin
      xyz="0.11906 -0.58734 0.069457"
      rpy="1.5708 0 0" />
    <parent
      link="base_link" />
    <child
      link="lb_wheel" />
    <axis
      xyz="0 0 1" />
    <limit
      effort="100"
      velocity="2" />
  </joint>



  <link
    name="Lidar">
    <inertial>
      <origin
        xyz="0 0 0"
        rpy="0 0 0" />
      <mass
        value="0.5" />
      <inertia
        ixx="0.01"
        ixy="0.01"
        ixz="0.01"
        iyy="0"
        iyz="0"
        izz="0" />
    </inertial>
    <visual>
      <origin
        xyz="0 0 0"
        rpy="1.5707 0 0" />
      <geometry>
        <mesh
          filename="package://bot_description/meshes/Lidar.STL" />
      </geometry>
      <material
        name="">
        <color
          rgba="1 1 1 1" />
      </material>
    </visual>
    <collision>
      <origin
        xyz="0 0 0"
        rpy="1.5707 0 0" />
      <geometry>
        <mesh
          filename="package://bot_description/meshes/Lidar.STL" />
      </geometry>
    </collision>
  </link>
  <joint
    name="Lidarjoint"
    type="fixed">
    <origin
      xyz="-0.040937 -0.38734 0.21546"
      rpy="0 0 0" />
    <parent
      link="base_link" />
    <child
      link="Lidar" />
  </joint>

          <gazebo reference="Lidar">
            <material>Gazebo/Black</material>
        </gazebo>
                <gazebo reference="Lidar">
            <sensor type="ray" name="rplidar">
                <pose>0 0 0 0 0 0</pose>
                <visualize>false</visualize>
                <update_rate>5.5</update_rate>
                <ray>
                    <scan>
                      <horizontal>
                        <samples>360</samples>
                        <resolution>1</resolution>
                        <min_angle>-3</min_angle>
                        <max_angle>3</max_angle>
                      </horizontal>
                    </scan>
                    <range>
                      <min>0.10</min>
                      <max>6.0</max>
                      <resolution>0.01</resolution>
                    </range>
                    <noise>
                      <type>gaussian</type>
                      <mean>0.0</mean>
                      <stddev>0.01</stddev>
                    </noise>
                </ray>
                <plugin name="gazebo_rplidar" filename="libgazebo_ros_laser.so">
                    <topicName>/scan</topicName>
                    <frameName>Lidar</frameName>
                </plugin>
            </sensor>
        </gazebo>

        <transmission name="rf_joint_trans">
            <type>transmission_interface/SimpleTransmission</type>
            <joint name="rfjoint" >
                <hardwareInterface>hardware_interface/VelocityJointInterface</hardwareInterface>
            </joint>
            <actuator name="rf_joint_motor">
                <hardwareInterface>hardware_interface/VelocityJointInterface</hardwareInterface>
                <mechanicalReduction>1</mechanicalReduction>
            </actuator>
        </transmission>
        <transmission name="rb_joint_trans">
            <type>transmission_interface/SimpleTransmission</type>
            <joint name="rbjoint" >
                <hardwareInterface>hardware_interface/VelocityJointInterface</hardwareInterface>
            </joint>
            <actuator name="rb_joint_motor">
                <hardwareInterface>hardware_interface/VelocityJointInterface</hardwareInterface>
                <mechanicalReduction>1</mechanicalReduction>
            </actuator>
        </transmission>
        <transmission name="lf_joint_trans">
            <type>transmission_interface/SimpleTransmission</type>
            <joint name="lfjoint" >
                <hardwareInterface>hardware_interface/VelocityJointInterface</hardwareInterface>
            </joint>
            <actuator name="lf_joint_motor">
                <hardwareInterface>hardware_interface/VelocityJointInterface</hardwareInterface>
                <mechanicalReduction>1</mechanicalReduction>
            </actuator>
        </transmission>
        <transmission name="lb_joint_trans">
            <type>transmission_interface/SimpleTransmission</type>
            <joint name="lbjoint" >
                <hardwareInterface>hardware_interface/VelocityJointInterface</hardwareInterface>
            </joint>
            <actuator name="lb_joint_motor">
                <hardwareInterface>hardware_interface/VelocityJointInterface</hardwareInterface>
                <mechanicalReduction>1</mechanicalReduction>
            </actuator>
        </transmission>


        <gazebo>
            <plugin name="differential_drive_controller" 
                    filename="libgazebo_ros_diff_drive.so">
                <rosDebugLevel>Debug</rosDebugLevel>
                <publishWheelTF>true</publishWheelTF>
                <robotNamespace>/</robotNamespace>
                <publishTf>1</publishTf>
                <publishWheelJointState>true</publishWheelJointState>
                <alwaysOn>true</alwaysOn>
                <updateRate>100.0</updateRate>
                <legacyMode>true</legacyMode>
                <leftJoint>rfjoint</leftJoint>
                <rightJoint>lfjoint</rightJoint>
                <wheelSeparation>0.43</wheelSeparation>
                <wheelDiameter>0.152</wheelDiameter>
                <broadcastTF>1</broadcastTF>
                <wheelTorque>30</wheelTorque>
                <wheelAcceleration>1.8</wheelAcceleration>
                <commandTopic>cmd_vel</commandTopic>
                <odometryFrame>odom</odometryFrame> 
                <odometryTopic>odom</odometryTopic> 
                <robotBaseFrame>base_link</robotBaseFrame>
            </plugin>
        </gazebo> 
</robot>
